Workbook

Sheet Cover
B3: Configuration Parameters
B5: Generated: | C5: April 07, 2026
B6: Solution: | C6: Intelligent Document Processing
B7: Customer: | C7: [Customer Name]
B8: Version: | C8: 1.0
B9: Status: | C9: Draft
C12: eoframework.org

Sheet All Parameters (Read Only)
A1: Total Parameters | B1: Categories | C1: Required | D1: Confidential/Secret
A2: 134 | B2: 8 | C2: 124 | D2: 6
A4: Parameter Name | B4: Category | C4: Production | D4: Test | E4: DR | F4: Description | G4: Required | H4: Data Type | I4: Validation Rules | J4: Security Level | K4: Owner Team | L4: Dependencies | M4: Notes | N4: Last Updated
A5: =IF('Project'!A3="","",'Project'!A3) | B5: Project | C5: =IF('Project'!B3="","",'Project'!B3) | D5: =IF('Project'!C3="","",'Project'!C3) | E5: =IF('Project'!D3="","",'Project'!D3) | F5: =IF('Project'!E3="","",'Project'!E3) | G5: =IF('Project'!F3="","",'Project'!F3) | H5: =IF('Project'!G3="","",'Project'!G3) | I5: =IF('Project'!H3="","",'Project'!H3) | J5: =IF('Project'!I3="","",'Project'!I3) | ... N5: =IF('Project'!M3="","",'Project'!M3)
A6: =IF('Project'!A4="","",'Project'!A4) | B6: Project | C6: =IF('Project'!B4="","",'Project'!B4) | D6: =IF('Project'!C4="","",'Project'!C4) | E6: =IF('Project'!D4="","",'Project'!D4) | F6: =IF('Project'!E4="","",'Project'!E4) | G6: =IF('Project'!F4="","",'Project'!F4) | H6: =IF('Project'!G4="","",'Project'!G4) | I6: =IF('Project'!H4="","",'Project'!H4) | J6: =IF('Project'!I4="","",'Project'!I4) | ... N6: =IF('Project'!M4="","",'Project'!M4)
A7: =IF('Project'!A5="","",'Project'!A5) | B7: Project | C7: =IF('Project'!B5="","",'Project'!B5) | D7: =IF('Project'!C5="","",'Project'!C5) | E7: =IF('Project'!D5="","",'Project'!D5) | F7: =IF('Project'!E5="","",'Project'!E5) | G7: =IF('Project'!F5="","",'Project'!F5) | H7: =IF('Project'!G5="","",'Project'!G5) | I7: =IF('Project'!H5="","",'Project'!H5) | J7: =IF('Project'!I5="","",'Project'!I5) | ... N7: =IF('Project'!M5="","",'Project'!M5)
A8: =IF('Project'!A6="","",'Project'!A6) | B8: Project | C8: =IF('Project'!B6="","",'Project'!B6) | D8: =IF('Project'!C6="","",'Project'!C6) | E8: =IF('Project'!D6="","",'Project'!D6) | F8: =IF('Project'!E6="","",'Project'!E6) | G8: =IF('Project'!F6="","",'Project'!F6) | H8: =IF('Project'!G6="","",'Project'!G6) | I8: =IF('Project'!H6="","",'Project'!H6) | J8: =IF('Project'!I6="","",'Project'!I6) | ... N8: =IF('Project'!M6="","",'Project'!M6)
A9: =IF('Project'!A7="","",'Project'!A7) | B9: Project | C9: =IF('Project'!B7="","",'Project'!B7) | D9: =IF('Project'!C7="","",'Project'!C7) | E9: =IF('Project'!D7="","",'Project'!D7) | F9: =IF('Project'!E7="","",'Project'!E7) | G9: =IF('Project'!F7="","",'Project'!F7) | H9: =IF('Project'!G7="","",'Project'!G7) | I9: =IF('Project'!H7="","",'Project'!H7) | J9: =IF('Project'!I7="","",'Project'!I7) | ... N9: =IF('Project'!M7="","",'Project'!M7)
A10: =IF('Project'!A8="","",'Project'!A8) | B10: Project | C10: =IF('Project'!B8="","",'Project'!B8) | D10: =IF('Project'!C8="","",'Project'!C8) | E10: =IF('Project'!D8="","",'Project'!D8) | F10: =IF('Project'!E8="","",'Project'!E8) | G10: =IF('Project'!F8="","",'Project'!F8) | H10: =IF('Project'!G8="","",'Project'!G8) | I10: =IF('Project'!H8="","",'Project'!H8) | J10: =IF('Project'!I8="","",'Project'!I8) | ... N10: =IF('Project'!M8="","",'Project'!M8)
A11: =IF('Project'!A9="","",'Project'!A9) | B11: Project | C11: =IF('Project'!B9="","",'Project'!B9) | D11: =IF('Project'!C9="","",'Project'!C9) | E11: =IF('Project'!D9="","",'Project'!D9) | F11: =IF('Project'!E9="","",'Project'!E9) | G11: =IF('Project'!F9="","",'Project'!F9) | H11: =IF('Project'!G9="","",'Project'!G9) | I11: =IF('Project'!H9="","",'Project'!H9) | J11: =IF('Project'!I9="","",'Project'!I9) | ... N11: =IF('Project'!M9="","",'Project'!M9)
A12: =IF('Project'!A10="","",'Project'!A10) | B12: Project | C12: =IF('Project'!B10="","",'Project'!B10) | D12: =IF('Project'!C10="","",'Project'!C10) | E12: =IF('Project'!D10="","",'Project'!D10) | F12: =IF('Project'!E10="","",'Project'!E10) | G12: =IF('Project'!F10="","",'Project'!F10) | H12: =IF('Project'!G10="","",'Project'!G10) | I12: =IF('Project'!H10="","",'Project'!H10) | J12: =IF('Project'!I10="","",'Project'!I10) | ... N12: =IF('Project'!M10="","",'Project'!M10)
A13: =IF('Project'!A11="","",'Project'!A11) | B13: Project | C13: =IF('Project'!B11="","",'Project'!B11) | D13: =IF('Project'!C11="","",'Project'!C11) | E13: =IF('Project'!D11="","",'Project'!D11) | F13: =IF('Project'!E11="","",'Project'!E11) | G13: =IF('Project'!F11="","",'Project'!F11) | H13: =IF('Project'!G11="","",'Project'!G11) | I13: =IF('Project'!H11="","",'Project'!H11) | J13: =IF('Project'!I11="","",'Project'!I11) | ... N13: =IF('Project'!M11="","",'Project'!M11)
A14: =IF('Project'!A12="","",'Project'!A12) | B14: Project | C14: =IF('Project'!B12="","",'Project'!B12) | D14: =IF('Project'!C12="","",'Project'!C12) | E14: =IF('Project'!D12="","",'Project'!D12) | F14: =IF('Project'!E12="","",'Project'!E12) | G14: =IF('Project'!F12="","",'Project'!F12) | H14: =IF('Project'!G12="","",'Project'!G12) | I14: =IF('Project'!H12="","",'Project'!H12) | J14: =IF('Project'!I12="","",'Project'!I12) | ... N14: =IF('Project'!M12="","",'Project'!M12)
A15: =IF('Security'!A3="","",'Security'!A3) | B15: Security | C15: =IF('Security'!B3="","",'Security'!B3) | D15: =IF('Security'!C3="","",'Security'!C3) | E15: =IF('Security'!D3="","",'Security'!D3) | F15: =IF('Security'!E3="","",'Security'!E3) | G15: =IF('Security'!F3="","",'Security'!F3) | H15: =IF('Security'!G3="","",'Security'!G3) | I15: =IF('Security'!H3="","",'Security'!H3) | J15: =IF('Security'!I3="","",'Security'!I3) | ... N15: =IF('Security'!M3="","",'Security'!M3)
A16: =IF('Security'!A4="","",'Security'!A4) | B16: Security | C16: =IF('Security'!B4="","",'Security'!B4) | D16: =IF('Security'!C4="","",'Security'!C4) | E16: =IF('Security'!D4="","",'Security'!D4) | F16: =IF('Security'!E4="","",'Security'!E4) | G16: =IF('Security'!F4="","",'Security'!F4) | H16: =IF('Security'!G4="","",'Security'!G4) | I16: =IF('Security'!H4="","",'Security'!H4) | J16: =IF('Security'!I4="","",'Security'!I4) | ... N16: =IF('Security'!M4="","",'Security'!M4)
A17: =IF('Security'!A5="","",'Security'!A5) | B17: Security | C17: =IF('Security'!B5="","",'Security'!B5) | D17: =IF('Security'!C5="","",'Security'!C5) | E17: =IF('Security'!D5="","",'Security'!D5) | F17: =IF('Security'!E5="","",'Security'!E5) | G17: =IF('Security'!F5="","",'Security'!F5) | H17: =IF('Security'!G5="","",'Security'!G5) | I17: =IF('Security'!H5="","",'Security'!H5) | J17: =IF('Security'!I5="","",'Security'!I5) | ... N17: =IF('Security'!M5="","",'Security'!M5)
A18: =IF('Security'!A6="","",'Security'!A6) | B18: Security | C18: =IF('Security'!B6="","",'Security'!B6) | D18: =IF('Security'!C6="","",'Security'!C6) | E18: =IF('Security'!D6="","",'Security'!D6) | F18: =IF('Security'!E6="","",'Security'!E6) | G18: =IF('Security'!F6="","",'Security'!F6) | H18: =IF('Security'!G6="","",'Security'!G6) | I18: =IF('Security'!H6="","",'Security'!H6) | J18: =IF('Security'!I6="","",'Security'!I6) | ... N18: =IF('Security'!M6="","",'Security'!M6)
A19: =IF('Security'!A7="","",'Security'!A7) | B19: Security | C19: =IF('Security'!B7="","",'Security'!B7) | D19: =IF('Security'!C7="","",'Security'!C7) | E19: =IF('Security'!D7="","",'Security'!D7) | F19: =IF('Security'!E7="","",'Security'!E7) | G19: =IF('Security'!F7="","",'Security'!F7) | H19: =IF('Security'!G7="","",'Security'!G7) | I19: =IF('Security'!H7="","",'Security'!H7) | J19: =IF('Security'!I7="","",'Security'!I7) | ... N19: =IF('Security'!M7="","",'Security'!M7)
A20: =IF('Security'!A8="","",'Security'!A8) | B20: Security | C20: =IF('Security'!B8="","",'Security'!B8) | D20: =IF('Security'!C8="","",'Security'!C8) | E20: =IF('Security'!D8="","",'Security'!D8) | F20: =IF('Security'!E8="","",'Security'!E8) | G20: =IF('Security'!F8="","",'Security'!F8) | H20: =IF('Security'!G8="","",'Security'!G8) | I20: =IF('Security'!H8="","",'Security'!H8) | J20: =IF('Security'!I8="","",'Security'!I8) | ... N20: =IF('Security'!M8="","",'Security'!M8)
A21: =IF('Security'!A9="","",'Security'!A9) | B21: Security | C21: =IF('Security'!B9="","",'Security'!B9) | D21: =IF('Security'!C9="","",'Security'!C9) | E21: =IF('Security'!D9="","",'Security'!D9) | F21: =IF('Security'!E9="","",'Security'!E9) | G21: =IF('Security'!F9="","",'Security'!F9) | H21: =IF('Security'!G9="","",'Security'!G9) | I21: =IF('Security'!H9="","",'Security'!H9) | J21: =IF('Security'!I9="","",'Security'!I9) | ... N21: =IF('Security'!M9="","",'Security'!M9)
A22: =IF('Security'!A10="","",'Security'!A10) | B22: Security | C22: =IF('Security'!B10="","",'Security'!B10) | D22: =IF('Security'!C10="","",'Security'!C10) | E22: =IF('Security'!D10="","",'Security'!D10) | F22: =IF('Security'!E10="","",'Security'!E10) | G22: =IF('Security'!F10="","",'Security'!F10) | H22: =IF('Security'!G10="","",'Security'!G10) | I22: =IF('Security'!H10="","",'Security'!H10) | J22: =IF('Security'!I10="","",'Security'!I10) | ... N22: =IF('Security'!M10="","",'Security'!M10)
A23: =IF('Security'!A11="","",'Security'!A11) | B23: Security | C23: =IF('Security'!B11="","",'Security'!B11) | D23: =IF('Security'!C11="","",'Security'!C11) | E23: =IF('Security'!D11="","",'Security'!D11) | F23: =IF('Security'!E11="","",'Security'!E11) | G23: =IF('Security'!F11="","",'Security'!F11) | H23: =IF('Security'!G11="","",'Security'!G11) | I23: =IF('Security'!H11="","",'Security'!H11) | J23: =IF('Security'!I11="","",'Security'!I11) | ... N23: =IF('Security'!M11="","",'Security'!M11)
A24: =IF('Security'!A12="","",'Security'!A12) | B24: Security | C24: =IF('Security'!B12="","",'Security'!B12) | D24: =IF('Security'!C12="","",'Security'!C12) | E24: =IF('Security'!D12="","",'Security'!D12) | F24: =IF('Security'!E12="","",'Security'!E12) | G24: =IF('Security'!F12="","",'Security'!F12) | H24: =IF('Security'!G12="","",'Security'!G12) | I24: =IF('Security'!H12="","",'Security'!H12) | J24: =IF('Security'!I12="","",'Security'!I12) | ... N24: =IF('Security'!M12="","",'Security'!M12)
A25: =IF('Security'!A13="","",'Security'!A13) | B25: Security | C25: =IF('Security'!B13="","",'Security'!B13) | D25: =IF('Security'!C13="","",'Security'!C13) | E25: =IF('Security'!D13="","",'Security'!D13) | F25: =IF('Security'!E13="","",'Security'!E13) | G25: =IF('Security'!F13="","",'Security'!F13) | H25: =IF('Security'!G13="","",'Security'!G13) | I25: =IF('Security'!H13="","",'Security'!H13) | J25: =IF('Security'!I13="","",'Security'!I13) | ... N25: =IF('Security'!M13="","",'Security'!M13)
A26: =IF('Security'!A14="","",'Security'!A14) | B26: Security | C26: =IF('Security'!B14="","",'Security'!B14) | D26: =IF('Security'!C14="","",'Security'!C14) | E26: =IF('Security'!D14="","",'Security'!D14) | F26: =IF('Security'!E14="","",'Security'!E14) | G26: =IF('Security'!F14="","",'Security'!F14) | H26: =IF('Security'!G14="","",'Security'!G14) | I26: =IF('Security'!H14="","",'Security'!H14) | J26: =IF('Security'!I14="","",'Security'!I14) | ... N26: =IF('Security'!M14="","",'Security'!M14)
... A29: =IF('Security'!A17="","",'Security'!A17) | B29: Security | C29: =IF('Security'!B17="","",'Security'!B17) | D29: =IF('Security'!C17="","",'Security'!C17) | E29: =IF('Security'!D17="","",'Security'!D17) | F29: =IF('Security'!E17="","",'Security'!E17) | G29: =IF('Security'!F17="","",'Security'!F17) | H29: =IF('Security'!G17="","",'Security'!G17) | I29: =IF('Security'!H17="","",'Security'!H17) | J29: =IF('Security'!I17="","",'Security'!I17) | ... N29: =IF('Security'!M17="","",'Security'!M17)
A30: =IF('Storage'!A3="","",'Storage'!A3) | B30: Storage | C30: =IF('Storage'!B3="","",'Storage'!B3) | D30: =IF('Storage'!C3="","",'Storage'!C3) | E30: =IF('Storage'!D3="","",'Storage'!D3) | F30: =IF('Storage'!E3="","",'Storage'!E3) | G30: =IF('Storage'!F3="","",'Storage'!F3) | H30: =IF('Storage'!G3="","",'Storage'!G3) | I30: =IF('Storage'!H3="","",'Storage'!H3) | J30: =IF('Storage'!I3="","",'Storage'!I3) | ... N30: =IF('Storage'!M3="","",'Storage'!M3)
A31: =IF('Storage'!A4="","",'Storage'!A4) | B31: Storage | C31: =IF('Storage'!B4="","",'Storage'!B4) | D31: =IF('Storage'!C4="","",'Storage'!C4) | E31: =IF('Storage'!D4="","",'Storage'!D4) | F31: =IF('Storage'!E4="","",'Storage'!E4) | G31: =IF('Storage'!F4="","",'Storage'!F4) | H31: =IF('Storage'!G4="","",'Storage'!G4) | I31: =IF('Storage'!H4="","",'Storage'!H4) | J31: =IF('Storage'!I4="","",'Storage'!I4) | ... N31: =IF('Storage'!M4="","",'Storage'!M4)
A32: =IF('Storage'!A5="","",'Storage'!A5) | B32: Storage | C32: =IF('Storage'!B5="","",'Storage'!B5) | D32: =IF('Storage'!C5="","",'Storage'!C5) | E32: =IF('Storage'!D5="","",'Storage'!D5) | F32: =IF('Storage'!E5="","",'Storage'!E5) | G32: =IF('Storage'!F5="","",'Storage'!F5) | H32: =IF('Storage'!G5="","",'Storage'!G5) | I32: =IF('Storage'!H5="","",'Storage'!H5) | J32: =IF('Storage'!I5="","",'Storage'!I5) | ... N32: =IF('Storage'!M5="","",'Storage'!M5)
A33: =IF('Storage'!A6="","",'Storage'!A6) | B33: Storage | C33: =IF('Storage'!B6="","",'Storage'!B6) | D33: =IF('Storage'!C6="","",'Storage'!C6) | E33: =IF('Storage'!D6="","",'Storage'!D6) | F33: =IF('Storage'!E6="","",'Storage'!E6) | G33: =IF('Storage'!F6="","",'Storage'!F6) | H33: =IF('Storage'!G6="","",'Storage'!G6) | I33: =IF('Storage'!H6="","",'Storage'!H6) | J33: =IF('Storage'!I6="","",'Storage'!I6) | ... N33: =IF('Storage'!M6="","",'Storage'!M6)
A34: =IF('Storage'!A7="","",'Storage'!A7) | B34: Storage | C34: =IF('Storage'!B7="","",'Storage'!B7) | D34: =IF('Storage'!C7="","",'Storage'!C7) | E34: =IF('Storage'!D7="","",'Storage'!D7) | F34: =IF('Storage'!E7="","",'Storage'!E7) | G34: =IF('Storage'!F7="","",'Storage'!F7) | H34: =IF('Storage'!G7="","",'Storage'!G7) | I34: =IF('Storage'!H7="","",'Storage'!H7) | J34: =IF('Storage'!I7="","",'Storage'!I7) | ... N34: =IF('Storage'!M7="","",'Storage'!M7)
A35: =IF('Storage'!A8="","",'Storage'!A8) | B35: Storage | C35: =IF('Storage'!B8="","",'Storage'!B8) | D35: =IF('Storage'!C8="","",'Storage'!C8) | E35: =IF('Storage'!D8="","",'Storage'!D8) | F35: =IF('Storage'!E8="","",'Storage'!E8) | G35: =IF('Storage'!F8="","",'Storage'!F8) | H35: =IF('Storage'!G8="","",'Storage'!G8) | I35: =IF('Storage'!H8="","",'Storage'!H8) | J35: =IF('Storage'!I8="","",'Storage'!I8) | ... N35: =IF('Storage'!M8="","",'Storage'!M8)
A36: =IF('Storage'!A9="","",'Storage'!A9) | B36: Storage | C36: =IF('Storage'!B9="","",'Storage'!B9) | D36: =IF('Storage'!C9="","",'Storage'!C9) | E36: =IF('Storage'!D9="","",'Storage'!D9) | F36: =IF('Storage'!E9="","",'Storage'!E9) | G36: =IF('Storage'!F9="","",'Storage'!F9) | H36: =IF('Storage'!G9="","",'Storage'!G9) | I36: =IF('Storage'!H9="","",'Storage'!H9) | J36: =IF('Storage'!I9="","",'Storage'!I9) | ... N36: =IF('Storage'!M9="","",'Storage'!M9)
A37: =IF('Storage'!A10="","",'Storage'!A10) | B37: Storage | C37: =IF('Storage'!B10="","",'Storage'!B10) | D37: =IF('Storage'!C10="","",'Storage'!C10) | E37: =IF('Storage'!D10="","",'Storage'!D10) | F37: =IF('Storage'!E10="","",'Storage'!E10) | G37: =IF('Storage'!F10="","",'Storage'!F10) | H37: =IF('Storage'!G10="","",'Storage'!G10) | I37: =IF('Storage'!H10="","",'Storage'!H10) | J37: =IF('Storage'!I10="","",'Storage'!I10) | ... N37: =IF('Storage'!M10="","",'Storage'!M10)
A38: =IF('Storage'!A11="","",'Storage'!A11) | B38: Storage | C38: =IF('Storage'!B11="","",'Storage'!B11) | D38: =IF('Storage'!C11="","",'Storage'!C11) | E38: =IF('Storage'!D11="","",'Storage'!D11) | F38: =IF('Storage'!E11="","",'Storage'!E11) | G38: =IF('Storage'!F11="","",'Storage'!F11) | H38: =IF('Storage'!G11="","",'Storage'!G11) | I38: =IF('Storage'!H11="","",'Storage'!H11) | J38: =IF('Storage'!I11="","",'Storage'!I11) | ... N38: =IF('Storage'!M11="","",'Storage'!M11)
A39: =IF('Storage'!A12="","",'Storage'!A12) | B39: Storage | C39: =IF('Storage'!B12="","",'Storage'!B12) | D39: =IF('Storage'!C12="","",'Storage'!C12) | E39: =IF('Storage'!D12="","",'Storage'!D12) | F39: =IF('Storage'!E12="","",'Storage'!E12) | G39: =IF('Storage'!F12="","",'Storage'!F12) | H39: =IF('Storage'!G12="","",'Storage'!G12) | I39: =IF('Storage'!H12="","",'Storage'!H12) | J39: =IF('Storage'!I12="","",'Storage'!I12) | ... N39: =IF('Storage'!M12="","",'Storage'!M12)
A40: =IF('Database'!A3="","",'Database'!A3) | B40: Database | C40: =IF('Database'!B3="","",'Database'!B3) | D40: =IF('Database'!C3="","",'Database'!C3) | E40: =IF('Database'!D3="","",'Database'!D3) | F40: =IF('Database'!E3="","",'Database'!E3) | G40: =IF('Database'!F3="","",'Database'!F3) | H40: =IF('Database'!G3="","",'Database'!G3) | I40: =IF('Database'!H3="","",'Database'!H3) | J40: =IF('Database'!I3="","",'Database'!I3) | ... N40: =IF('Database'!M3="","",'Database'!M3)
A41: =IF('Database'!A4="","",'Database'!A4) | B41: Database | C41: =IF('Database'!B4="","",'Database'!B4) | D41: =IF('Database'!C4="","",'Database'!C4) | E41: =IF('Database'!D4="","",'Database'!D4) | F41: =IF('Database'!E4="","",'Database'!E4) | G41: =IF('Database'!F4="","",'Database'!F4) | H41: =IF('Database'!G4="","",'Database'!G4) | I41: =IF('Database'!H4="","",'Database'!H4) | J41: =IF('Database'!I4="","",'Database'!I4) | ... N41: =IF('Database'!M4="","",'Database'!M4)
A42: =IF('Database'!A5="","",'Database'!A5) | B42: Database | C42: =IF('Database'!B5="","",'Database'!B5) | D42: =IF('Database'!C5="","",'Database'!C5) | E42: =IF('Database'!D5="","",'Database'!D5) | F42: =IF('Database'!E5="","",'Database'!E5) | G42: =IF('Database'!F5="","",'Database'!F5) | H42: =IF('Database'!G5="","",'Database'!G5) | I42: =IF('Database'!H5="","",'Database'!H5) | J42: =IF('Database'!I5="","",'Database'!I5) | ... N42: =IF('Database'!M5="","",'Database'!M5)
A43: =IF('Database'!A6="","",'Database'!A6) | B43: Database | C43: =IF('Database'!B6="","",'Database'!B6) | D43: =IF('Database'!C6="","",'Database'!C6) | E43: =IF('Database'!D6="","",'Database'!D6) | F43: =IF('Database'!E6="","",'Database'!E6) | G43: =IF('Database'!F6="","",'Database'!F6) | H43: =IF('Database'!G6="","",'Database'!G6) | I43: =IF('Database'!H6="","",'Database'!H6) | J43: =IF('Database'!I6="","",'Database'!I6) | ... N43: =IF('Database'!M6="","",'Database'!M6)
...

Sheet Project
A1: Project Parameters
A2: Parameter Name | B2: Production | C2: Test | D2: DR | E2: Description | F2: Required | G2: Data Type | H2: Validation Rules | I2: Security Level | J2: Owner Team | K2: Dependencies | L2: Notes | M2: Last Updated
A3: solution.name | B3: intelligent-document-processing | C3: intelligent-document-processing | D3: intelligent-document-processing | E3: Solution name for resource naming | F3: Yes | G3: String | H3: Valid string value | I3: Public | J3: Development | L3: IDP solution identifier | M3: 2025-12-01
A4: solution.abbr | B4: idp | C4: idp | D4: idp | E4: Solution abbreviation (3-4 chars) | F4: Yes | G4: String | H4: Valid string value | I4: Public | J4: Development | L4: Used in resource naming prefix | M4: 2025-12-01
A5: solution.provider_name | B5: aws | C5: aws | D5: aws | E5: Provider organization name | F5: Yes | G5: String | H5: Valid string value | I5: Public | J5: Development | L5: AWS provider | M5: 2025-12-01
A6: solution.category_name | B6: ai | C6: ai | D6: ai | E6: Solution category | F6: Yes | G6: String | H6: Valid string value | I6: Public | J6: Development | L6: AI category | M6: 2025-12-01
A7: aws.region | B7: us-east-1 | C7: us-east-1 | D7: us-west-2 | E7: Primary AWS region | F7: Yes | G7: String | H7: Valid region | I7: Public | J7: Infrastructure | L7: From SOW AWS_REGION | M7: 2025-12-01
A8: aws.dr_region | B8: us-west-2 | C8: us-west-2 | D8: us-east-1 | E8: DR region | F8: Yes | G8: String | H8: Valid region | I8: Public | J8: Infrastructure | L8: From SOW AWS_DR_REGION | M8: 2025-12-01
A9: aws.profile | E9: AWS CLI profile (optional) | F9: No | G9: String | H9: Valid profile | I9: Confidential | J9: Infrastructure | L9: Leave empty for default | M9: 2025-12-01
A10: ownership.cost_center | B10: CC-IDP-001 | C10: CC-IDP-001 | D10: CC-IDP-001 | E10: Cost center | F10: Yes | G10: String | H10: Valid string | I10: Public | J10: Infrastructure | L10: From SOW COST_ALLOCATION_TAGS | M10: 2025-12-01
A11: ownership.owner_email | B11: idp-team@example.com | C11: idp-team@example.com | D11: idp-team@example.com | E11: Owner email | F11: Yes | G11: String | H11: Valid email | I11: Confidential | J11: Infrastructure | L11: Team notifications | M11: 2025-12-01
A12: ownership.project_code | B12: PRJ-IDP-2025 | C12: PRJ-IDP-2025 | D12: PRJ-IDP-2025 | E12: Project code | F12: Yes | G12: String | H12: Valid string | I12: Public | J12: Infrastructure | L12: Tracking code | M12: 2025-12-01

Sheet Security
A1: Security Parameters
A2: Parameter Name | B2: Production | C2: Test | D2: DR | E2: Description | F2: Required | G2: Data Type | H2: Validation Rules | I2: Security Level | J2: Owner Team | K2: Dependencies | L2: Notes | M2: Last Updated
A3: security.kms_deletion_window_days | B3: 30 | C3: 7 | D3: 30 | E3: KMS key deletion window (days) | F3: Yes | G3: Integer | H3: 7-30 | I3: Public | J3: Security | L3: Protection period | M3: 2025-12-01
A4: security.enable_kms_key_rotation | B4: true | C4: true | D4: true | E4: Enable KMS key rotation | F4: Yes | G4: Boolean | H4: true|false | I4: Public | J4: Security | L4: Security best practice | M4: 2025-12-01
A5: auth.enabled | B5: true | C5: true | D5: true | E5: Enable Cognito authentication | F5: Yes | G5: Boolean | H5: true|false | I5: Public | J5: Security | L5: API auth | M5: 2025-12-01
A6: auth.username_attributes | B6: ["email"] | C6: ["email"] | D6: ["email"] | E6: Username attributes | F6: Yes | G6: List(String) | H6: Valid attributes | I6: Public | J6: Security | L6: Email login | M6: 2025-12-01
A7: auth.auto_verified_attributes | B7: ["email"] | C7: ["email"] | D7: ["email"] | E7: Auto-verified attributes | F7: Yes | G7: List(String) | H7: Valid attributes | I7: Public | J7: Security | L7: Email verification | M7: 2025-12-01
A8: auth.password_minimum_length | B8: 12 | C8: 8 | D8: 12 | E8: Minimum password length | F8: Yes | G8: Integer | H8: 8-99 | I8: Public | J8: Security | L8: Password policy | M8: 2025-12-01
A9: auth.password_require_lowercase | B9: true | C9: true | D9: true | E9: Require lowercase | F9: Yes | G9: Boolean | H9: true|false | I9: Public | J9: Security | L9: Password policy | M9: 2025-12-01
A10: auth.password_require_numbers | B10: true | C10: true | D10: true | E10: Require numbers | F10: Yes | G10: Boolean | H10: true|false | I10: Public | J10: Security | L10: Password policy | M10: 2025-12-01
A11: auth.password_require_symbols | B11: true | C11: false | D11: true | E11: Require symbols | F11: Yes | G11: Boolean | H11: true|false | I11: Public | J11: Security | L11: Password policy | M11: 2025-12-01
A12: auth.password_require_uppercase | B12: true | C12: true | D12: true | E12: Require uppercase | F12: Yes | G12: Boolean | H12: true|false | I12: Public | J12: Security | L12: Password policy | M12: 2025-12-01
A13: auth.mfa_configuration | B13: OPTIONAL | C13: OFF | D13: OPTIONAL | E13: MFA configuration | F13: Yes | G13: String | H13: OFF|OPTIONAL|ON | I13: Public | J13: Security | L13: Multi-factor auth | M13: 2025-12-01
A14: auth.advanced_security_mode | B14: AUDIT | C14: OFF | D14: AUDIT | E14: Advanced security mode | F14: Yes | G14: String | H14: OFF|AUDIT|ENFORCED | I14: Public | J14: Security | L14: Threat detection | M14: 2025-12-01
A15: auth.domain | E15: Cognito domain prefix | F15: No | G15: String | H15: Valid domain | I15: Public | J15: Security | L15: Custom domain | M15: 2025-12-01
A16: auth.callback_urls | B16: [] | C16: [] | D16: [] | E16: OAuth callback URLs | F16: No | G16: List(String) | H16: Valid URLs | I16: Public | J16: Security | L16: OAuth config | M16: 2025-12-01
A17: auth.logout_urls | B17: [] | C17: [] | D17: [] | E17: OAuth logout URLs | F17: No | G17: List(String) | H17: Valid URLs | I17: Public | J17: Security | L17: OAuth config | M17: 2025-12-01

Sheet Storage
A1: Storage Parameters
A2: Parameter Name | B2: Production | C2: Test | D2: DR | E2: Description | F2: Required | G2: Data Type | H2: Validation Rules | I2: Security Level | J2: Owner Team | K2: Dependencies | L2: Notes | M2: Last Updated
A3: storage.force_destroy | B3: false | C3: true | D3: false | E3: Allow S3 bucket destruction | F3: Yes | G3: Boolean | H3: true|false | I3: Public | J3: Infrastructure | L3: Test only | M3: 2025-12-01
A4: storage.versioning_enabled | B4: true | C4: true | D4: true | E4: Enable S3 versioning | F4: Yes | G4: Boolean | H4: true|false | I4: Public | J4: Infrastructure | L4: DR requirement | M4: 2025-12-01
A5: storage.transition_to_ia_days | B5: 30 | C5: 30 | D5: 30 | E5: Transition to S3-IA (days) | F5: Yes | G5: Integer | H5: Positive integer | I5: Public | J5: Infrastructure | L5: Cost optimization | M5: 2025-12-01
A6: storage.transition_to_glacier_days | B6: 90 | C6: 60 | D6: 90 | E6: Transition to Glacier (days) | F6: Yes | G6: Integer | H6: Positive integer | I6: Public | J6: Infrastructure | L6: Long-term storage | M6: 2025-12-01
A7: storage.document_expiration_days | B7: 365 | C7: 90 | D7: 365 | E7: Document expiration (days) | F7: Yes | G7: Integer | H7: Positive integer | I7: Public | J7: Infrastructure | L7: Data retention | M7: 2025-12-01
A8: storage.noncurrent_version_expiration_days | B8: 30 | C8: 7 | D8: 30 | E8: Noncurrent version expiration | F8: Yes | G8: Integer | H8: Positive integer | I8: Public | J8: Infrastructure | L8: Version cleanup | M8: 2025-12-01
A9: storage.enable_direct_upload | B9: true | C9: true | D9: true | E9: Enable direct S3 upload | F9: Yes | G9: Boolean | H9: true|false | I9: Public | J9: Infrastructure | L9: Presigned URLs | M9: 2025-12-01
A10: storage.cors_allowed_origins | B10: ["*"] | C10: ["*"] | D10: ["*"] | E10: CORS allowed origins | F10: Yes | G10: List(String) | H10: Valid origins | I10: Public | J10: Infrastructure | L10: API access | M10: 2025-12-01
A11: storage.create_output_bucket | B11: true | C11: true | D11: true | E11: Create output bucket | F11: Yes | G11: Boolean | H11: true|false | I11: Public | J11: Infrastructure | L11: Processed results | M11: 2025-12-01
A12: storage.output_expiration_days | B12: 30 | C12: 7 | D12: 30 | E12: Output expiration (days) | F12: Yes | G12: Integer | H12: Positive integer | I12: Public | J12: Infrastructure | L12: Results retention | M12: 2025-12-01

Sheet Database
A1: Database Parameters
A2: Parameter Name | B2: Production | C2: Test | D2: DR | E2: Description | F2: Required | G2: Data Type | H2: Validation Rules | I2: Security Level | J2: Owner Team | K2: Dependencies | L2: Notes | M2: Last Updated
A3: database.billing_mode | B3: PAY_PER_REQUEST | C3: PAY_PER_REQUEST | D3: PAY_PER_REQUEST | E3: DynamoDB billing mode | F3: Yes | G3: String | H3: PAY_PER_REQUEST|PROVISIONED | I3: Public | J3: Infrastructure | L3: On-demand for variable load | M3: 2025-12-01
A4: database.read_capacity | B4: 5 | C4: 5 | D4: 5 | E4: DynamoDB read capacity (PROVISIONED) | F4: Yes | G4: Integer | H4: Positive integer | I4: Public | J4: Infrastructure | L4: Only for PROVISIONED | M4: 2025-12-01
A5: database.write_capacity | B5: 5 | C5: 5 | D5: 5 | E5: DynamoDB write capacity (PROVISIONED) | F5: Yes | G5: Integer | H5: Positive integer | I5: Public | J5: Infrastructure | L5: Only for PROVISIONED | M5: 2025-12-01
A6: database.gsi_read_capacity | B6: 5 | C6: 5 | D6: 5 | E6: GSI read capacity (PROVISIONED) | F6: Yes | G6: Integer | H6: Positive integer | I6: Public | J6: Infrastructure | L6: Only for PROVISIONED | M6: 2025-12-01
A7: database.gsi_write_capacity | B7: 5 | C7: 5 | D7: 5 | E7: GSI write capacity (PROVISIONED) | F7: Yes | G7: Integer | H7: Positive integer | I7: Public | J7: Infrastructure | L7: Only for PROVISIONED | M7: 2025-12-01
A8: database.ttl_enabled | B8: true | C8: true | D8: true | E8: Enable TTL | F8: Yes | G8: Boolean | H8: true|false | I8: Public | J8: Infrastructure | L8: Auto-expire old records | M8: 2025-12-01
A9: database.point_in_time_recovery | B9: true | C9: false | D9: true | E9: Enable point-in-time recovery | F9: Yes | G9: Boolean | H9: true|false | I9: Public | J9: Infrastructure | L9: PITR backup | M9: 2025-12-01
A10: database.stream_enabled | B10: false | C10: false | D10: false | E10: Enable DynamoDB streams | F10: Yes | G10: Boolean | H10: true|false | I10: Public | J10: Infrastructure | L10: Event processing | M10: 2025-12-01
A11: database.stream_view_type | B11: NEW_AND_OLD_IMAGES | C11: NEW_AND_OLD_IMAGES | D11: NEW_AND_OLD_IMAGES | E11: Stream view type | F11: Yes | G11: String | H11: Valid stream type | I11: Public | J11: Infrastructure | L11: If streams enabled | M11: 2025-12-01
A12: database.enable_autoscaling | B12: false | C12: false | D12: false | E12: Enable autoscaling | F12: Yes | G12: Boolean | H12: true|false | I12: Public | J12: Infrastructure | L12: Only for PROVISIONED | M12: 2025-12-01
A13: database.autoscaling_min_read | B13: 5 | C13: 5 | D13: 5 | E13: Autoscaling min read | F13: Yes | G13: Integer | H13: Positive integer | I13: Public | J13: Infrastructure | L13: Only for PROVISIONED | M13: 2025-12-01
A14: database.autoscaling_max_read | B14: 100 | C14: 50 | D14: 100 | E14: Autoscaling max read | F14: Yes | G14: Integer | H14: Positive integer | I14: Public | J14: Infrastructure | L14: Only for PROVISIONED | M14: 2025-12-01
... A17: database.autoscaling_target_utilization | B17: 70 | C17: 70 | D17: 70 | E17: Autoscaling target utilization | F17: Yes | G17: Integer | H17: 0-100 | I17: Public | J17: Infrastructure | L17: Target percentage | M17: 2025-12-01

Sheet Application
A1: Application Parameters
A2: Parameter Name | B2: Production | C2: Test | D2: DR | E2: Description | F2: Required | G2: Data Type | H2: Validation Rules | I2: Security Level | J2: Owner Team | K2: Dependencies | L2: Notes | M2: Last Updated
A3: application.lambda_runtime | B3: python3.11 | C3: python3.11 | D3: python3.11 | E3: Lambda runtime | F3: Yes | G3: String | H3: Valid runtime | I3: Public | J3: Development | L3: Python 3.11 | M3: 2025-12-01
A4: application.lambda_vpc_enabled | B4: false | C4: false | D4: false | E4: Enable Lambda VPC mode | F4: Yes | G4: Boolean | H4: true|false | I4: Public | J4: Development | L4: Requires network.vpc_id and network.private_subnet_ids | M4: 2025-12-01
A5: textract.supported_document_types | B5: ["pdf", "png", "jpg", "jpeg", "tiff"] | C5: ["pdf", "png", "jpg", "jpeg", "tiff"] | D5: ["pdf", "png", "jpg", "jpeg", "tiff"] | E5: Supported document types | F5: Yes | G5: List(String) | H5: Valid types | I5: Public | J5: AI/ML Team | L5: Textract supported formats | M5: 2025-12-01
A6: textract.max_file_size_mb | B6: 50 | C6: 50 | D6: 50 | E6: Maximum file size (MB) | F6: Yes | G6: Integer | H6: 1-100 | I6: Public | J6: AI/ML Team | L6: Textract limit | M6: 2025-12-01
A7: textract.confidence_threshold | B7: 80 | C7: 80 | D7: 80 | E7: Minimum confidence for auto-processing | F7: Yes | G7: Integer | H7: 0-100 | I7: Public | J7: AI/ML Team | L7: Below routes to human review | M7: 2025-12-01
A8: textract.polling_interval_seconds | B8: 30 | C8: 30 | D8: 30 | E8: Async polling interval | F8: Yes | G8: Integer | H8: 1-300 | I8: Public | J8: AI/ML Team | L8: Check job status | M8: 2025-12-01
A9: textract.max_polling_attempts | B9: 20 | C9: 20 | D9: 20 | E9: Max polling attempts | F9: Yes | G9: Integer | H9: 1-100 | I9: Public | J9: AI/ML Team | L9: Timeout protection | M9: 2025-12-01
A10: textract.enable_tables | B10: true | C10: true | D10: true | E10: Enable table extraction | F10: Yes | G10: Boolean | H10: true|false | I10: Public | J10: AI/ML Team | L10: Extract tables | M10: 2025-12-01
A11: textract.enable_forms | B11: true | C11: true | D11: true | E11: Enable form extraction | F11: Yes | G11: Boolean | H11: true|false | I11: Public | J11: AI/ML Team | L11: Extract forms | M11: 2025-12-01
A12: textract.enable_queries | B12: false | C12: false | D12: false | E12: Enable queries feature | F12: Yes | G12: Boolean | H12: true|false | I12: Public | J12: AI/ML Team | L12: Custom queries | M12: 2025-12-01
A13: textract.enable_signatures | B13: false | C13: false | D13: false | E13: Enable signature detection | F13: Yes | G13: Boolean | H13: true|false | I13: Public | J13: AI/ML Team | L13: Signature detection | M13: 2025-12-01
A14: textract.enable_expense | B14: false | C14: false | D14: false | E14: Enable expense analysis | F14: Yes | G14: Boolean | H14: true|false | I14: Public | J14: AI/ML Team | L14: Receipt/invoice | M14: 2025-12-01
... A23: human_review.use_private_workforce | B23: true | C23: true | D23: true | E23: Use private workforce | F23: Yes | G23: Boolean | H23: true|false | I23: Public | J23: AI/ML Team | L23: Internal reviewers | M23: 2025-12-01
A24: human_review.workteam_arn | E24: SageMaker workteam ARN | F24: No | G24: String | H24: Valid ARN | I24: Confidential | J24: AI/ML Team | L24: Private team ARN | M24: 2025-12-01
A25: human_review.task_price_usd | B25: 0.05 | C25: 0.05 | D25: 0.05 | E25: Task price (USD) | F25: Yes | G25: String | H25: Valid number | I25: Public | J25: AI/ML Team | L25: Per task cost | M25: 2025-12-01
A26: human_review.task_title | B26: Document Review Task | C26: Document Review Task | D26: Document Review Task | E26: Task title | F26: Yes | G26: String | H26: Valid string | I26: Public | J26: AI/ML Team | L26: Shown to workers | M26: 2025-12-01
A27: human_review.task_description | B27: Review the extracted document data and verify accuracy | C27: Review the extracted document data and verify accuracy | D27: Review the extracted document data and verify accuracy | E27: Task description | F27: Yes | G27: String | H27: Valid string | I27: Public | J27: AI/ML Team | L27: Worker instructions | M27: 2025-12-01
A28: human_review.task_count | B28: 1 | C28: 1 | D28: 1 | E28: Workers per task | F28: Yes | G28: Integer | H28: 1-10 | I28: Public | J28: AI/ML Team | L28: Redundancy | M28: 2025-12-01
A29: human_review.task_availability_seconds | B29: 43200 | C29: 43200 | D29: 43200 | E29: Task availability (seconds) | F29: Yes | G29: Integer | H29: Positive integer | I29: Public | J29: AI/ML Team | L29: 12 hours | M29: 2025-12-01
A30: human_review.confidence_threshold | B30: 80 | C30: 80 | D30: 80 | E30: Confidence threshold | F30: Yes | G30: Integer | H30: 0-100 | I30: Public | J30: AI/ML Team | L30: Route to review | M30: 2025-12-01
A31: human_review.custom_ui_template | E31: Custom UI template | F31: No | G31: String | H31: Valid path | I31: Public | J31: AI/ML Team | L31: Optional custom UI | M31: 2025-12-01
A32: api.version | B32: 1.0.0 | C32: 1.0.0 | D32: 1.0.0 | E32: API version | F32: Yes | G32: String | H32: Semantic versioning | I32: Public | J32: Development | L32: API versioning | M32: 2025-12-01
A33: api.stage_name | B33: v1 | C33: v1 | D33: v1 | E33: API Gateway stage | F33: Yes | G33: String | H33: Valid stage | I33: Public | J33: Development | L33: Deployment stage | M33: 2025-12-01
A34: api.endpoint_type | B34: REGIONAL | C34: REGIONAL | D34: REGIONAL | E34: API endpoint type | F34: Yes | G34: String | H34: REGIONAL|EDGE|PRIVATE | I34: Public | J34: Development | L34: Regional API | M34: 2025-12-01
A35: api.enable_cors | B35: true | C35: true | D35: true | E35: Enable CORS | F35: Yes | G35: Boolean | H35: true|false | I35: Public | J35: Development | L35: Cross-origin access | M35: 2025-12-01
A36: api.max_file_size_mb | B36: 50 | C36: 50 | D36: 50 | E36: Max upload size (MB) | F36: Yes | G36: Integer | H36: 1-100 | I36: Public | J36: Development | L36: Request limit | M36: 2025-12-01
A37: api.default_page_size | B37: 20 | C37: 20 | D37: 20 | E37: Default pagination size | F37: Yes | G37: Integer | H37: 1-100 | I37: Public | J37: Development | L37: List results | M37: 2025-12-01
A38: api.throttling_burst_limit | B38: 1000 | C38: 100 | D38: 1000 | E38: API burst limit | F38: Yes | G38: Integer | H38: 0-10000 | I38: Public | J38: Development | L38: From SOW | M38: 2025-12-01
A39: api.throttling_rate_limit | B39: 500 | C39: 50 | D39: 500 | E39: API steady-state rate | F39: Yes | G39: Integer | H39: 0-10000 | I39: Public | J39: Development | L39: From SOW | M39: 2025-12-01
A40: api.allowed_content_types | B40: ["application/pdf", "image/png", "image/jpeg", "image/tiff"] | C40: ["application/pdf", "image/png", "image/jpeg", "image/tiff"] | D40: ["application/pdf", "image/png", "image/jpeg", "image/tiff"] | E40: Allowed content types | F40: Yes | G40: List(String) | H40: Valid types | I40: Public | J40: Development | L40: Upload validation | M40: 2025-12-01

Sheet Monitoring
A1: Monitoring Parameters
A2: Parameter Name | B2: Production | C2: Test | D2: DR | E2: Description | F2: Required | G2: Data Type | H2: Validation Rules | I2: Security Level | J2: Owner Team | K2: Dependencies | L2: Notes | M2: Last Updated
A3: logging.retention_days | B3: 30 | C3: 7 | D3: 30 | E3: CloudWatch log retention | F3: Yes | G3: Integer | H3: Positive integer | I3: Public | J3: Operations | L3: Log retention | M3: 2025-12-01
A4: logging.step_functions_log_level | B4: ERROR | C4: ALL | D4: ERROR | E4: Step Functions log level | F4: Yes | G4: String | H4: ALL|ERROR|FATAL|OFF | I4: Public | J4: Operations | L4: SFN logging | M4: 2025-12-01
A5: logging.api_gateway_log_level | B5: INFO | C5: INFO | D5: INFO | E5: API Gateway log level | F5: Yes | G5: String | H5: OFF|ERROR|INFO | I5: Public | J5: Operations | L5: API logging | M5: 2025-12-01
A6: logging.data_trace_enabled | B6: false | C6: true | D6: false | E6: Enable data tracing | F6: Yes | G6: Boolean | H6: true|false | I6: Public | J6: Operations | L6: Request/response logs | M6: 2025-12-01
A7: monitoring.xray_enabled | B7: true | C7: true | D7: true | E7: Enable X-Ray tracing | F7: Yes | G7: Boolean | H7: true|false | I7: Public | J7: Operations | L7: Distributed tracing | M7: 2025-12-01
A8: monitoring.enable_alarms | B8: true | C8: false | D8: true | E8: Enable CloudWatch alarms | F8: Yes | G8: Boolean | H8: true|false | I8: Public | J8: Operations | L8: Alert notifications | M8: 2025-12-01
A9: monitoring.sns_topic_arn | E9: SNS topic for alerts | F9: No | G9: String | H9: Valid ARN | I9: Confidential | J9: Operations | L9: Alert destination | M9: 2025-12-01
A10: monitoring.api_error_threshold | B10: 10 | C10: 50 | D10: 10 | E10: API 5xx error threshold | F10: Yes | G10: Integer | H10: Positive integer | I10: Public | J10: Operations | L10: Alert trigger | M10: 2025-12-01
A11: monitoring.api_4xx_threshold | B11: 100 | C11: 200 | D11: 100 | E11: API 4xx error threshold | F11: Yes | G11: Integer | H11: Positive integer | I11: Public | J11: Operations | L11: Client error alert | M11: 2025-12-01
A12: monitoring.api_latency_p95_ms | B12: 2000 | C12: 5000 | D12: 2000 | E12: API p95 latency threshold (ms) | F12: Yes | G12: Integer | H12: Positive integer | I12: Public | J12: Operations | L12: <2 sec target | M12: 2025-12-01
A13: monitoring.sfn_failure_threshold | B13: 5 | C13: 20 | D13: 5 | E13: Step Functions failure threshold | F13: Yes | G13: Integer | H13: Positive integer | I13: Public | J13: Operations | L13: Alert trigger | M13: 2025-12-01
A14: monitoring.lambda_error_rate_percent | B14: 5 | C14: 10 | D14: 5 | E14: Lambda error rate threshold (%) | F14: Yes | G14: Integer | H14: 0-100 | I14: Public | J14: Operations | L14: Alert on errors | M14: 2025-12-01
A15: monitoring.lambda_duration_p95_ms | B15: 60000 | C15: 60000 | D15: 60000 | E15: Lambda p95 duration threshold (ms) | F15: Yes | G15: Integer | H15: Positive integer | I15: Public | J15: Operations | L15: Performance alert | M15: 2025-12-01

Sheet DR
A1: DR Parameters
A2: Parameter Name | B2: Production | C2: Test | D2: DR | E2: Description | F2: Required | G2: Data Type | H2: Validation Rules | I2: Security Level | J2: Owner Team | K2: Dependencies | L2: Notes | M2: Last Updated
A3: dr.enabled | B3: true | C3: false | D3: true | E3: Enable DR infrastructure | F3: Yes | G3: Boolean | H3: true|false | I3: Public | J3: Operations | L3: Master DR toggle | M3: 2025-12-01
A4: dr.strategy | B4: ACTIVE_PASSIVE | C4: BACKUP_ONLY | D4: ACTIVE_PASSIVE | E4: DR strategy | F4: Yes | G4: String | H4: ACTIVE_PASSIVE|ACTIVE_ACTIVE|BACKUP_ONLY | I4: Public | J4: Operations | L4: Recovery approach | M4: 2025-12-01
A5: dr.rto_minutes | B5: 240 | C5: 480 | D5: 240 | E5: Recovery Time Objective (minutes) | F5: Yes | G5: Integer | H5: Positive integer | I5: Public | J5: Operations | L5: Target recovery time | M5: 2025-12-01
A6: dr.rpo_minutes | B6: 60 | C6: 1440 | D6: 60 | E6: Recovery Point Objective (minutes) | F6: Yes | G6: Integer | H6: Positive integer | I6: Public | J6: Operations | L6: Max data loss window | M6: 2025-12-01
A7: dr.failover_mode | B7: manual | C7: manual | D7: manual | E7: Failover mode | F7: Yes | G7: String | H7: manual|automatic | I7: Public | J7: Operations | L7: Manual for safety | M7: 2025-12-01
A8: dr.replication_enabled | B8: true | C8: false | D8: false | E8: Enable cross-region replication | F8: Yes | G8: Boolean | H8: true|false | I8: Public | J8: Operations | L8: S3 CRR and DynamoDB | M8: 2025-12-01
A9: dr.storage_replication_class | B9: STANDARD | C9: STANDARD | D9: STANDARD | E9: DR storage class | F9: Yes | G9: String | H9: Valid class | I9: Public | J9: Operations | L9: S3 storage class | M9: 2025-12-01
A10: dr.enable_replication_time_control | B10: true | C10: true | D10: true | E10: Enable replication time control | F10: Yes | G10: Boolean | H10: true|false | I10: Public | J10: Operations | L10: Predictable replication | M10: 2025-12-01
A11: dr.vault_enabled | B11: true | C11: false | D11: true | E11: Enable DR backup vault | F11: Yes | G11: Boolean | H11: true|false | I11: Public | J11: Operations | L11: DR vault in DR region | M11: 2025-12-01
A12: dr.vault_kms_deletion_window_days | B12: 30 | C12: 30 | D12: 30 | E12: DR KMS deletion window | F12: Yes | G12: Integer | H12: 7-30 | I12: Public | J12: Operations | L12: Protection period | M12: 2025-12-01
A13: dr.vault_transition_to_ia_days | B13: 30 | C13: 30 | D13: 30 | E13: DR vault transition to IA | F13: Yes | G13: Integer | H13: Positive integer | I13: Public | J13: Operations | L13: Cost optimization | M13: 2025-12-01
A14: dr.vault_noncurrent_version_expiration_days | B14: 90 | C14: 90 | D14: 90 | E14: DR vault noncurrent expiration | F14: Yes | G14: Integer | H14: Positive integer | I14: Public | J14: Operations | L14: Version cleanup | M14: 2025-12-01
... A19: dr.weekly_backup_retention_days | B19: 90 | C19: 90 | D19: 90 | E19: DR weekly retention | F19: Yes | G19: Integer | H19: Positive integer | I19: Public | J19: Operations | L19: 3 months | M19: 2025-12-01
A20: dr.test_schedule | B20: cron(0 2 ? * SUN *) | D20: cron(0 2 ? * SUN *) | E20: DR test schedule | F20: No | G20: String | H20: Valid cron | I20: Public | J20: Operations | L20: Weekly DR test | M20: 2025-12-01
A21: dr.notification_email | B21: dr-alerts@example.com | C21: dr-alerts@example.com | D21: dr-alerts@example.com | E21: DR notification email | F21: No | G21: String | H21: Valid email | I21: Confidential | J21: Operations | L21: Alert notifications | M21: 2025-12-01

Sheet Best Practices
A1: Best Practices Parameters
A2: Parameter Name | B2: Production | C2: Test | D2: DR | E2: Description | F2: Required | G2: Data Type | H2: Validation Rules | I2: Security Level | J2: Owner Team | K2: Dependencies | L2: Notes | M2: Last Updated
A3: budget.enabled | B3: true | C3: false | D3: true | E3: [Cost Optimization] Enable AWS Budgets tracking | F3: Yes | G3: Boolean | H3: true|false | I3: Public | J3: Operations | L3: Proactive cost monitoring for AI services | M3: 2025-12-01
A4: budget.monthly_amount | B4: 1500 | C4: 500 | D4: 1500 | E4: [Cost Optimization] Monthly budget limit (USD) | F4: Yes | G4: Integer | H4: Valid integer | I4: Public | J4: Operations | L4: Based on SOW cost estimates | M4: 2025-12-01
A5: budget.alert_thresholds | B5: [50, 80, 100] | C5: [80, 100] | D5: [50, 80, 100] | E5: [Cost Optimization] Budget alert thresholds (%) | F5: Yes | G5: List(Number) | H5: 0-100 | I5: Public | J5: Operations | L5: Multi-tier alerts | M5: 2025-12-01
A6: budget.enable_forecast_alert | B6: true | C6: false | D6: true | E6: [Cost Optimization] Enable forecasted spend alerts | F6: Yes | G6: Boolean | H6: true|false | I6: Public | J6: Operations | L6: ML-based spend forecasting | M6: 2025-12-01
A7: budget.alert_emails | B7: [] | C7: [] | D7: [] | E7: [Cost Optimization] Alert email addresses | F7: No | G7: List(String) | H7: Valid emails | I7: Confidential | J7: Operations | L7: Additional email recipients | M7: 2025-12-01
A8: config_rules.enabled | B8: true | C8: false | D8: true | E8: [Operational Excellence] Enable AWS Config rules | F8: Yes | G8: Boolean | H8: true|false | I8: Public | J8: Operations | L8: Compliance monitoring and drift detection | M8: 2025-12-01
A9: config_rules.enable_recorder | B9: true | C9: true | D9: true | E9: [Operational Excellence] Enable Config recorder | F9: Yes | G9: Boolean | H9: true|false | I9: Public | J9: Operations | L9: Records configuration changes | M9: 2025-12-01
A10: config_rules.retention_days | B10: 365 | C10: 90 | D10: 365 | E10: [Operational Excellence] Config history retention (days) | F10: Yes | G10: Integer | H10: Positive integer | I10: Public | J10: Operations | L10: One-year retention for audits | M10: 2025-12-01
A11: config_rules.enable_security_rules | B11: true | C11: true | D11: true | E11: [Operational Excellence] Enable security compliance rules | F11: Yes | G11: Boolean | H11: true|false | I11: Public | J11: Operations | L11: S3 encryption KMS rotation checks | M11: 2025-12-01
A12: config_rules.enable_reliability_rules | B12: true | C12: false | D12: true | E12: [Operational Excellence] Enable reliability compliance rules | F12: Yes | G12: Boolean | H12: true|false | I12: Public | J12: Operations | L12: Backup and versioning checks | M12: 2025-12-01
A13: guardduty.enabled | B13: true | C13: false | D13: true | E13: [Security] Enable GuardDuty threat detection | F13: Yes | G13: Boolean | H13: true|false | I13: Public | J13: Operations | L13: ML-based threat detection | M13: 2025-12-01
A14: guardduty.enable_s3_protection | B14: true | C14: true | D14: true | E14: [Security] Enable S3 data event monitoring | F14: Yes | G14: Boolean | H14: true|false | I14: Public | J14: Operations | L14: Detects suspicious S3 access | M14: 2025-12-01
... A16: guardduty.severity_threshold | B16: 7 | C16: 7 | D16: 7 | E16: [Security] Minimum alert severity threshold (1-10) | F16: Yes | G16: Integer | H16: 1-10 | I16: Public | J16: Operations | L16: 7+ filters to high/critical findings | M16: 2025-12-01
